2020-05-01 18:13:52 [ERROR] : 获取 [360] 威胁情报异常
Traceback (most recent call last):
  File "D:\workspace\Github\threat-broadcast\src\crawler\_base_crawler.py", line 57, in cve_msgs
    new_cves = self.get_cves()
  File "D:\workspace\Github\threat-broadcast\src\crawler\cert360.py", line 47, in get_cves
    timeout = self.timeout
  File "S:\04_work\python\python27\lib\site-packages\requests\api.py", line 75, in get
    return request('get', url, params=params, **kwargs)
  File "S:\04_work\python\python27\lib\site-packages\requests\api.py", line 60, in request
    return session.request(method=method, url=url, **kwargs)
  File "S:\04_work\python\python27\lib\site-packages\requests\sessions.py", line 533, in request
    resp = self.send(prep, **send_kwargs)
  File "S:\04_work\python\python27\lib\site-packages\requests\sessions.py", line 646, in send
    r = adapter.send(request, **kwargs)
  File "S:\04_work\python\python27\lib\site-packages\requests\adapters.py", line 516, in send
    raise ConnectionError(e, request=request)
ConnectionError: HTTPSConnectionPool(host='cert.360.cn', port=443): Max retries exceeded with url: /warning/searchbypage?start=0&length=6 (Caused by NewConnectionError('<urllib3.connection.VerifiedHTTPSConnection object at 0x00000000041CEC18>: Failed to establish a new connection: [Errno 11001] getaddrinfo failed',))
2020-05-01 18:13:52 [ERROR] : Traceback (most recent call last):
  File "D:\workspace\Github\threat-broadcast\src\crawler\_base_crawler.py", line 57, in cve_msgs
    new_cves = self.get_cves()
  File "D:\workspace\Github\threat-broadcast\src\crawler\cert360.py", line 47, in get_cves
    timeout = self.timeout
  File "S:\04_work\python\python27\lib\site-packages\requests\api.py", line 75, in get
    return request('get', url, params=params, **kwargs)
  File "S:\04_work\python\python27\lib\site-packages\requests\api.py", line 60, in request
    return session.request(method=method, url=url, **kwargs)
  File "S:\04_work\python\python27\lib\site-packages\requests\sessions.py", line 533, in request
    resp = self.send(prep, **send_kwargs)
  File "S:\04_work\python\python27\lib\site-packages\requests\sessions.py", line 646, in send
    r = adapter.send(request, **kwargs)
  File "S:\04_work\python\python27\lib\site-packages\requests\adapters.py", line 516, in send
    raise ConnectionError(e, request=request)
ConnectionError: HTTPSConnectionPool(host='cert.360.cn', port=443): Max retries exceeded with url: /warning/searchbypage?start=0&length=6 (Caused by NewConnectionError('<urllib3.connection.VerifiedHTTPSConnection object at 0x00000000041CEC18>: Failed to establish a new connection: [Errno 11001] getaddrinfo failed',))
Traceback (most recent call last):
  File "D:\workspace\Github\threat-broadcast\src\crawler\_base_crawler.py", line 57, in cve_msgs
    new_cves = self.get_cves()
  File "D:\workspace\Github\threat-broadcast\src\crawler\cert360.py", line 47, in get_cves
    timeout = self.timeout
  File "S:\04_work\python\python27\lib\site-packages\requests\api.py", line 75, in get
    return request('get', url, params=params, **kwargs)
  File "S:\04_work\python\python27\lib\site-packages\requests\api.py", line 60, in request
    return session.request(method=method, url=url, **kwargs)
  File "S:\04_work\python\python27\lib\site-packages\requests\sessions.py", line 533, in request
    resp = self.send(prep, **send_kwargs)
  File "S:\04_work\python\python27\lib\site-packages\requests\sessions.py", line 646, in send
    r = adapter.send(request, **kwargs)
  File "S:\04_work\python\python27\lib\site-packages\requests\adapters.py", line 516, in send
    raise ConnectionError(e, request=request)
ConnectionError: HTTPSConnectionPool(host='cert.360.cn', port=443): Max retries exceeded with url: /warning/searchbypage?start=0&length=6 (Caused by NewConnectionError('<urllib3.connection.VerifiedHTTPSConnection object at 0x00000000041CEC18>: Failed to establish a new connection: [Errno 11001] getaddrinfo failed',))
2020-05-01 18:24:26 [ERROR] : Error: 无法发送邮件
Traceback (most recent call last):
  File "D:\workspace\Github\threat-broadcast\src\notice\mail.py", line 33, in to_mail
    smtpObj.login(sender, password)
  File "S:\04_work\python\python27\lib\smtplib.py", line 623, in login
    raise SMTPAuthenticationError(code, resp)
SMTPAuthenticationError: (535, 'Error: authentication failed')
2020-05-01 18:24:26 [ERROR] : Traceback (most recent call last):
  File "D:\workspace\Github\threat-broadcast\src\notice\mail.py", line 33, in to_mail
    smtpObj.login(sender, password)
  File "S:\04_work\python\python27\lib\smtplib.py", line 623, in login
    raise SMTPAuthenticationError(code, resp)
SMTPAuthenticationError: (535, 'Error: authentication failed')
Traceback (most recent call last):
  File "D:\workspace\Github\threat-broadcast\src\notice\mail.py", line 33, in to_mail
    smtpObj.login(sender, password)
  File "S:\04_work\python\python27\lib\smtplib.py", line 623, in login
    raise SMTPAuthenticationError(code, resp)
SMTPAuthenticationError: (535, 'Error: authentication failed')
2020-05-01 18:25:13 [ERROR] : Error: 无法发送邮件
Traceback (most recent call last):
  File "D:\workspace\Github\threat-broadcast\src\notice\mail.py", line 36, in to_mail
    smtpObj = smtplib.SMTP(smtp)
  File "S:\04_work\python\python27\lib\smtplib.py", line 256, in __init__
    (code, msg) = self.connect(host, port)
  File "S:\04_work\python\python27\lib\smtplib.py", line 317, in connect
    self.sock = self._get_socket(host, port, self.timeout)
  File "S:\04_work\python\python27\lib\smtplib.py", line 292, in _get_socket
    return socket.create_connection((host, port), timeout)
  File "S:\04_work\python\python27\lib\socket.py", line 557, in create_connection
    for res in getaddrinfo(host, port, 0, SOCK_STREAM):
gaierror: [Errno 11001] getaddrinfo failed
2020-05-01 18:25:13 [ERROR] : Traceback (most recent call last):
  File "D:\workspace\Github\threat-broadcast\src\notice\mail.py", line 36, in to_mail
    smtpObj = smtplib.SMTP(smtp)
  File "S:\04_work\python\python27\lib\smtplib.py", line 256, in __init__
    (code, msg) = self.connect(host, port)
  File "S:\04_work\python\python27\lib\smtplib.py", line 317, in connect
    self.sock = self._get_socket(host, port, self.timeout)
  File "S:\04_work\python\python27\lib\smtplib.py", line 292, in _get_socket
    return socket.create_connection((host, port), timeout)
  File "S:\04_work\python\python27\lib\socket.py", line 557, in create_connection
    for res in getaddrinfo(host, port, 0, SOCK_STREAM):
gaierror: [Errno 11001] getaddrinfo failed
Traceback (most recent call last):
  File "D:\workspace\Github\threat-broadcast\src\notice\mail.py", line 36, in to_mail
    smtpObj = smtplib.SMTP(smtp)
  File "S:\04_work\python\python27\lib\smtplib.py", line 256, in __init__
    (code, msg) = self.connect(host, port)
  File "S:\04_work\python\python27\lib\smtplib.py", line 317, in connect
    self.sock = self._get_socket(host, port, self.timeout)
  File "S:\04_work\python\python27\lib\smtplib.py", line 292, in _get_socket
    return socket.create_connection((host, port), timeout)
  File "S:\04_work\python\python27\lib\socket.py", line 557, in create_connection
    for res in getaddrinfo(host, port, 0, SOCK_STREAM):
gaierror: [Errno 11001] getaddrinfo failed
2020-05-01 18:27:29 [ERROR] : Error: 无法发送邮件
Traceback (most recent call last):
  File "D:\workspace\Github\threat-broadcast\src\notice\mail.py", line 36, in to_mail
    smtpObj = smtplib.SMTP(smtp)
  File "S:\04_work\python\python27\lib\smtplib.py", line 256, in __init__
    (code, msg) = self.connect(host, port)
  File "S:\04_work\python\python27\lib\smtplib.py", line 317, in connect
    self.sock = self._get_socket(host, port, self.timeout)
  File "S:\04_work\python\python27\lib\smtplib.py", line 292, in _get_socket
    return socket.create_connection((host, port), timeout)
  File "S:\04_work\python\python27\lib\socket.py", line 557, in create_connection
    for res in getaddrinfo(host, port, 0, SOCK_STREAM):
gaierror: [Errno 11001] getaddrinfo failed
2020-05-01 18:27:29 [ERROR] : Traceback (most recent call last):
  File "D:\workspace\Github\threat-broadcast\src\notice\mail.py", line 36, in to_mail
    smtpObj = smtplib.SMTP(smtp)
  File "S:\04_work\python\python27\lib\smtplib.py", line 256, in __init__
    (code, msg) = self.connect(host, port)
  File "S:\04_work\python\python27\lib\smtplib.py", line 317, in connect
    self.sock = self._get_socket(host, port, self.timeout)
  File "S:\04_work\python\python27\lib\smtplib.py", line 292, in _get_socket
    return socket.create_connection((host, port), timeout)
  File "S:\04_work\python\python27\lib\socket.py", line 557, in create_connection
    for res in getaddrinfo(host, port, 0, SOCK_STREAM):
gaierror: [Errno 11001] getaddrinfo failed
Traceback (most recent call last):
  File "D:\workspace\Github\threat-broadcast\src\notice\mail.py", line 36, in to_mail
    smtpObj = smtplib.SMTP(smtp)
  File "S:\04_work\python\python27\lib\smtplib.py", line 256, in __init__
    (code, msg) = self.connect(host, port)
  File "S:\04_work\python\python27\lib\smtplib.py", line 317, in connect
    self.sock = self._get_socket(host, port, self.timeout)
  File "S:\04_work\python\python27\lib\smtplib.py", line 292, in _get_socket
    return socket.create_connection((host, port), timeout)
  File "S:\04_work\python\python27\lib\socket.py", line 557, in create_connection
    for res in getaddrinfo(host, port, 0, SOCK_STREAM):
gaierror: [Errno 11001] getaddrinfo failed
2020-05-01 18:28:24 [ERROR] : Error: 无法发送邮件
Traceback (most recent call last):
  File "D:\workspace\Github\threat-broadcast\src\notice\mail.py", line 36, in to_mail
    smtpObj = smtplib.SMTP(smtp)
  File "S:\04_work\python\python27\lib\smtplib.py", line 256, in __init__
    (code, msg) = self.connect(host, port)
  File "S:\04_work\python\python27\lib\smtplib.py", line 317, in connect
    self.sock = self._get_socket(host, port, self.timeout)
  File "S:\04_work\python\python27\lib\smtplib.py", line 292, in _get_socket
    return socket.create_connection((host, port), timeout)
  File "S:\04_work\python\python27\lib\socket.py", line 557, in create_connection
    for res in getaddrinfo(host, port, 0, SOCK_STREAM):
gaierror: [Errno 11001] getaddrinfo failed
2020-05-01 18:28:24 [ERROR] : Traceback (most recent call last):
  File "D:\workspace\Github\threat-broadcast\src\notice\mail.py", line 36, in to_mail
    smtpObj = smtplib.SMTP(smtp)
  File "S:\04_work\python\python27\lib\smtplib.py", line 256, in __init__
    (code, msg) = self.connect(host, port)
  File "S:\04_work\python\python27\lib\smtplib.py", line 317, in connect
    self.sock = self._get_socket(host, port, self.timeout)
  File "S:\04_work\python\python27\lib\smtplib.py", line 292, in _get_socket
    return socket.create_connection((host, port), timeout)
  File "S:\04_work\python\python27\lib\socket.py", line 557, in create_connection
    for res in getaddrinfo(host, port, 0, SOCK_STREAM):
gaierror: [Errno 11001] getaddrinfo failed
Traceback (most recent call last):
  File "D:\workspace\Github\threat-broadcast\src\notice\mail.py", line 36, in to_mail
    smtpObj = smtplib.SMTP(smtp)
  File "S:\04_work\python\python27\lib\smtplib.py", line 256, in __init__
    (code, msg) = self.connect(host, port)
  File "S:\04_work\python\python27\lib\smtplib.py", line 317, in connect
    self.sock = self._get_socket(host, port, self.timeout)
  File "S:\04_work\python\python27\lib\smtplib.py", line 292, in _get_socket
    return socket.create_connection((host, port), timeout)
  File "S:\04_work\python\python27\lib\socket.py", line 557, in create_connection
    for res in getaddrinfo(host, port, 0, SOCK_STREAM):
gaierror: [Errno 11001] getaddrinfo failed
2020-05-01 19:32:02 [ERROR] : [邮件] 推送威胁情报失败
Traceback (most recent call last):
  File "D:\workspace\Github\threat-broadcast\src\notice\mail.py", line 39, in to_mail
    smtpObj.sendmail(sender, receivers, email.as_string())
  File "S:\04_work\python\python27\lib\smtplib.py", line 748, in sendmail
    raise SMTPRecipientsRefused(senderrs)
SMTPRecipientsRefused: {';threatbroadcast@foxmail.com;289065406@qq.com': (550, 'Invalid User:')}
2020-05-01 19:32:02 [ERROR] : Traceback (most recent call last):
  File "D:\workspace\Github\threat-broadcast\src\notice\mail.py", line 39, in to_mail
    smtpObj.sendmail(sender, receivers, email.as_string())
  File "S:\04_work\python\python27\lib\smtplib.py", line 748, in sendmail
    raise SMTPRecipientsRefused(senderrs)
SMTPRecipientsRefused: {';threatbroadcast@foxmail.com;289065406@qq.com': (550, 'Invalid User:')}
Traceback (most recent call last):
  File "D:\workspace\Github\threat-broadcast\src\notice\mail.py", line 39, in to_mail
    smtpObj.sendmail(sender, receivers, email.as_string())
  File "S:\04_work\python\python27\lib\smtplib.py", line 748, in sendmail
    raise SMTPRecipientsRefused(senderrs)
SMTPRecipientsRefused: {';threatbroadcast@foxmail.com;289065406@qq.com': (550, 'Invalid User:')}
