2021-08-04 09:47:33 [ERROR] : 获取 Issue 的邮箱失败（国内 GraphQL 接口不稳定）
Traceback (most recent call last):
  File "D:\workspace\Github\threat-broadcast\src\notice\mail.py", line 111, in load_issue_receivers
    issues = _git.query_issues(gtk)
  File "D:\workspace\Github\threat-broadcast\src\utils\_git.py", line 52, in query_issues
    issues = data["data"]["repository"]["issues"]
KeyError: 'data'
2021-08-04 09:47:33 [ERROR] : Traceback (most recent call last):
  File "D:\workspace\Github\threat-broadcast\src\notice\mail.py", line 111, in load_issue_receivers
    issues = _git.query_issues(gtk)
  File "D:\workspace\Github\threat-broadcast\src\utils\_git.py", line 52, in query_issues
    issues = data["data"]["repository"]["issues"]
KeyError: 'data'
Traceback (most recent call last):
  File "D:\workspace\Github\threat-broadcast\src\notice\mail.py", line 111, in load_issue_receivers
    issues = _git.query_issues(gtk)
  File "D:\workspace\Github\threat-broadcast\src\utils\_git.py", line 52, in query_issues
    issues = data["data"]["repository"]["issues"]
KeyError: 'data'
2021-08-04 09:51:58 [ERROR] : 获取 Issue 的邮箱失败（国内 GraphQL 接口不稳定）
Traceback (most recent call last):
  File "D:\workspace\Github\threat-broadcast\src\notice\mail.py", line 111, in load_issue_receivers
    issues = _git.query_issues(gtk)
  File "D:\workspace\Github\threat-broadcast\src\utils\_git.py", line 52, in query_issues
    issues = data["data"]["repository"]["issues"]
KeyError: 'data'
2021-08-04 09:51:58 [ERROR] : Traceback (most recent call last):
  File "D:\workspace\Github\threat-broadcast\src\notice\mail.py", line 111, in load_issue_receivers
    issues = _git.query_issues(gtk)
  File "D:\workspace\Github\threat-broadcast\src\utils\_git.py", line 52, in query_issues
    issues = data["data"]["repository"]["issues"]
KeyError: 'data'
Traceback (most recent call last):
  File "D:\workspace\Github\threat-broadcast\src\notice\mail.py", line 111, in load_issue_receivers
    issues = _git.query_issues(gtk)
  File "D:\workspace\Github\threat-broadcast\src\utils\_git.py", line 52, in query_issues
    issues = data["data"]["repository"]["issues"]
KeyError: 'data'
