2020-12-02 00:17:57 [ERROR] : 获取 [CNVD] 威胁情报异常
Traceback (most recent call last):
  File "D:\workspace\Github\threat-broadcast\src\crawler\_base_crawler.py", line 62, in cves
    new_cves = self.get_cves()
  File "D:\workspace\Github\threat-broadcast\src\crawler\cnvd.py", line 58, in get_cves
    cve = self.to_cve(id)
  File "D:\workspace\Github\threat-broadcast\src\crawler\cnvd.py", line 71, in to_cve
    self.get_cve_info(cve, cve.url)
  File "D:\workspace\Github\threat-broadcast\src\crawler\cnvd.py", line 89, in get_cve_info
    time.sleep(2)
KeyboardInterrupt
2020-12-02 00:17:57 [ERROR] : Traceback (most recent call last):
  File "D:\workspace\Github\threat-broadcast\src\crawler\_base_crawler.py", line 62, in cves
    new_cves = self.get_cves()
  File "D:\workspace\Github\threat-broadcast\src\crawler\cnvd.py", line 58, in get_cves
    cve = self.to_cve(id)
  File "D:\workspace\Github\threat-broadcast\src\crawler\cnvd.py", line 71, in to_cve
    self.get_cve_info(cve, cve.url)
  File "D:\workspace\Github\threat-broadcast\src\crawler\cnvd.py", line 89, in get_cve_info
    time.sleep(2)
KeyboardInterrupt
Traceback (most recent call last):
  File "D:\workspace\Github\threat-broadcast\src\crawler\_base_crawler.py", line 62, in cves
    new_cves = self.get_cves()
  File "D:\workspace\Github\threat-broadcast\src\crawler\cnvd.py", line 58, in get_cves
    cve = self.to_cve(id)
  File "D:\workspace\Github\threat-broadcast\src\crawler\cnvd.py", line 71, in to_cve
    self.get_cve_info(cve, cve.url)
  File "D:\workspace\Github\threat-broadcast\src\crawler\cnvd.py", line 89, in get_cve_info
    time.sleep(2)
KeyboardInterrupt
2020-12-02 00:18:27 [ERROR] : 获取 [CNVD] 威胁情报异常
Traceback (most recent call last):
  File "D:\workspace\Github\threat-broadcast\src\crawler\_base_crawler.py", line 62, in cves
    new_cves = self.get_cves()
  File "D:\workspace\Github\threat-broadcast\src\crawler\cnvd.py", line 58, in get_cves
    cve = self.to_cve(id)
  File "D:\workspace\Github\threat-broadcast\src\crawler\cnvd.py", line 71, in to_cve
    self.get_cve_info(cve, cve.url)
  File "D:\workspace\Github\threat-broadcast\src\crawler\cnvd.py", line 89, in get_cve_info
    time.sleep(2)
KeyboardInterrupt
2020-12-02 00:18:27 [ERROR] : Traceback (most recent call last):
  File "D:\workspace\Github\threat-broadcast\src\crawler\_base_crawler.py", line 62, in cves
    new_cves = self.get_cves()
  File "D:\workspace\Github\threat-broadcast\src\crawler\cnvd.py", line 58, in get_cves
    cve = self.to_cve(id)
  File "D:\workspace\Github\threat-broadcast\src\crawler\cnvd.py", line 71, in to_cve
    self.get_cve_info(cve, cve.url)
  File "D:\workspace\Github\threat-broadcast\src\crawler\cnvd.py", line 89, in get_cve_info
    time.sleep(2)
KeyboardInterrupt
Traceback (most recent call last):
  File "D:\workspace\Github\threat-broadcast\src\crawler\_base_crawler.py", line 62, in cves
    new_cves = self.get_cves()
  File "D:\workspace\Github\threat-broadcast\src\crawler\cnvd.py", line 58, in get_cves
    cve = self.to_cve(id)
  File "D:\workspace\Github\threat-broadcast\src\crawler\cnvd.py", line 71, in to_cve
    self.get_cve_info(cve, cve.url)
  File "D:\workspace\Github\threat-broadcast\src\crawler\cnvd.py", line 89, in get_cve_info
    time.sleep(2)
KeyboardInterrupt
2020-12-02 00:19:03 [ERROR] : 获取 [CNVD] 威胁情报异常
Traceback (most recent call last):
  File "D:\workspace\Github\threat-broadcast\src\crawler\_base_crawler.py", line 62, in cves
    new_cves = self.get_cves()
  File "D:\workspace\Github\threat-broadcast\src\crawler\cnvd.py", line 58, in get_cves
    cve = self.to_cve(id)
  File "D:\workspace\Github\threat-broadcast\src\crawler\cnvd.py", line 71, in to_cve
    self.get_cve_info(cve, cve.url)
  File "D:\workspace\Github\threat-broadcast\src\crawler\cnvd.py", line 89, in get_cve_info
    time.sleep(2)
KeyboardInterrupt
2020-12-02 00:19:03 [ERROR] : Traceback (most recent call last):
  File "D:\workspace\Github\threat-broadcast\src\crawler\_base_crawler.py", line 62, in cves
    new_cves = self.get_cves()
  File "D:\workspace\Github\threat-broadcast\src\crawler\cnvd.py", line 58, in get_cves
    cve = self.to_cve(id)
  File "D:\workspace\Github\threat-broadcast\src\crawler\cnvd.py", line 71, in to_cve
    self.get_cve_info(cve, cve.url)
  File "D:\workspace\Github\threat-broadcast\src\crawler\cnvd.py", line 89, in get_cve_info
    time.sleep(2)
KeyboardInterrupt
Traceback (most recent call last):
  File "D:\workspace\Github\threat-broadcast\src\crawler\_base_crawler.py", line 62, in cves
    new_cves = self.get_cves()
  File "D:\workspace\Github\threat-broadcast\src\crawler\cnvd.py", line 58, in get_cves
    cve = self.to_cve(id)
  File "D:\workspace\Github\threat-broadcast\src\crawler\cnvd.py", line 71, in to_cve
    self.get_cve_info(cve, cve.url)
  File "D:\workspace\Github\threat-broadcast\src\crawler\cnvd.py", line 89, in get_cve_info
    time.sleep(2)
KeyboardInterrupt
2020-12-02 00:19:21 [ERROR] : 获取 [CNVD] 威胁情报异常
Traceback (most recent call last):
  File "D:\workspace\Github\threat-broadcast\src\crawler\_base_crawler.py", line 62, in cves
    new_cves = self.get_cves()
  File "D:\workspace\Github\threat-broadcast\src\crawler\cnvd.py", line 58, in get_cves
    cve = self.to_cve(id)
  File "D:\workspace\Github\threat-broadcast\src\crawler\cnvd.py", line 71, in to_cve
    self.get_cve_info(cve, cve.url)
  File "D:\workspace\Github\threat-broadcast\src\crawler\cnvd.py", line 89, in get_cve_info
    time.sleep(2)
KeyboardInterrupt
2020-12-02 00:19:21 [ERROR] : Traceback (most recent call last):
  File "D:\workspace\Github\threat-broadcast\src\crawler\_base_crawler.py", line 62, in cves
    new_cves = self.get_cves()
  File "D:\workspace\Github\threat-broadcast\src\crawler\cnvd.py", line 58, in get_cves
    cve = self.to_cve(id)
  File "D:\workspace\Github\threat-broadcast\src\crawler\cnvd.py", line 71, in to_cve
    self.get_cve_info(cve, cve.url)
  File "D:\workspace\Github\threat-broadcast\src\crawler\cnvd.py", line 89, in get_cve_info
    time.sleep(2)
KeyboardInterrupt
Traceback (most recent call last):
  File "D:\workspace\Github\threat-broadcast\src\crawler\_base_crawler.py", line 62, in cves
    new_cves = self.get_cves()
  File "D:\workspace\Github\threat-broadcast\src\crawler\cnvd.py", line 58, in get_cves
    cve = self.to_cve(id)
  File "D:\workspace\Github\threat-broadcast\src\crawler\cnvd.py", line 71, in to_cve
    self.get_cve_info(cve, cve.url)
  File "D:\workspace\Github\threat-broadcast\src\crawler\cnvd.py", line 89, in get_cve_info
    time.sleep(2)
KeyboardInterrupt
2020-12-02 00:39:26 [ERROR] : 获取 [CNVD] 威胁情报异常
Traceback (most recent call last):
  File "D:\workspace\Github\threat-broadcast\src\crawler\_base_crawler.py", line 62, in cves
    new_cves = self.get_cves()
  File "D:\workspace\Github\threat-broadcast\src\crawler\cnvd.py", line 58, in get_cves
    cve = self.to_cve(id)
  File "D:\workspace\Github\threat-broadcast\src\crawler\cnvd.py", line 72, in to_cve
    self.get_cve_info(cve, cve.url)
  File "D:\workspace\Github\threat-broadcast\src\crawler\cnvd.py", line 102, in get_cve_info
    time.sleep(2)
KeyboardInterrupt
2020-12-02 00:39:26 [ERROR] : Traceback (most recent call last):
  File "D:\workspace\Github\threat-broadcast\src\crawler\_base_crawler.py", line 62, in cves
    new_cves = self.get_cves()
  File "D:\workspace\Github\threat-broadcast\src\crawler\cnvd.py", line 58, in get_cves
    cve = self.to_cve(id)
  File "D:\workspace\Github\threat-broadcast\src\crawler\cnvd.py", line 72, in to_cve
    self.get_cve_info(cve, cve.url)
  File "D:\workspace\Github\threat-broadcast\src\crawler\cnvd.py", line 102, in get_cve_info
    time.sleep(2)
KeyboardInterrupt
Traceback (most recent call last):
  File "D:\workspace\Github\threat-broadcast\src\crawler\_base_crawler.py", line 62, in cves
    new_cves = self.get_cves()
  File "D:\workspace\Github\threat-broadcast\src\crawler\cnvd.py", line 58, in get_cves
    cve = self.to_cve(id)
  File "D:\workspace\Github\threat-broadcast\src\crawler\cnvd.py", line 72, in to_cve
    self.get_cve_info(cve, cve.url)
  File "D:\workspace\Github\threat-broadcast\src\crawler\cnvd.py", line 102, in get_cve_info
    time.sleep(2)
KeyboardInterrupt
2020-12-02 00:39:49 [ERROR] : 获取 [CNVD] 威胁情报异常
Traceback (most recent call last):
  File "D:\workspace\Github\threat-broadcast\src\crawler\_base_crawler.py", line 62, in cves
    new_cves = self.get_cves()
  File "D:\workspace\Github\threat-broadcast\src\crawler\cnvd.py", line 59, in get_cves
    cve = self.to_cve(id)
  File "D:\workspace\Github\threat-broadcast\src\crawler\cnvd.py", line 73, in to_cve
    self.get_cve_info(cve, cve.url)
  File "D:\workspace\Github\threat-broadcast\src\crawler\cnvd.py", line 103, in get_cve_info
    time.sleep(2)
KeyboardInterrupt
2020-12-02 00:39:49 [ERROR] : Traceback (most recent call last):
  File "D:\workspace\Github\threat-broadcast\src\crawler\_base_crawler.py", line 62, in cves
    new_cves = self.get_cves()
  File "D:\workspace\Github\threat-broadcast\src\crawler\cnvd.py", line 59, in get_cves
    cve = self.to_cve(id)
  File "D:\workspace\Github\threat-broadcast\src\crawler\cnvd.py", line 73, in to_cve
    self.get_cve_info(cve, cve.url)
  File "D:\workspace\Github\threat-broadcast\src\crawler\cnvd.py", line 103, in get_cve_info
    time.sleep(2)
KeyboardInterrupt
Traceback (most recent call last):
  File "D:\workspace\Github\threat-broadcast\src\crawler\_base_crawler.py", line 62, in cves
    new_cves = self.get_cves()
  File "D:\workspace\Github\threat-broadcast\src\crawler\cnvd.py", line 59, in get_cves
    cve = self.to_cve(id)
  File "D:\workspace\Github\threat-broadcast\src\crawler\cnvd.py", line 73, in to_cve
    self.get_cve_info(cve, cve.url)
  File "D:\workspace\Github\threat-broadcast\src\crawler\cnvd.py", line 103, in get_cve_info
    time.sleep(2)
KeyboardInterrupt
2020-12-02 00:48:21 [ERROR] : 获取 [CNVD] 威胁情报异常
Traceback (most recent call last):
  File "D:\workspace\Github\threat-broadcast\src\crawler\_base_crawler.py", line 62, in cves
    new_cves = self.get_cves()
  File "D:\workspace\Github\threat-broadcast\src\crawler\cnvd.py", line 58, in get_cves
    cve = self.to_cve(id)
  File "D:\workspace\Github\threat-broadcast\src\crawler\cnvd.py", line 73, in to_cve
    self.get_cve_info(cve, cve.url)
  File "D:\workspace\Github\threat-broadcast\src\crawler\cnvd.py", line 101, in get_cve_info
    time.sleep(2)
KeyboardInterrupt
2020-12-02 00:48:21 [ERROR] : Traceback (most recent call last):
  File "D:\workspace\Github\threat-broadcast\src\crawler\_base_crawler.py", line 62, in cves
    new_cves = self.get_cves()
  File "D:\workspace\Github\threat-broadcast\src\crawler\cnvd.py", line 58, in get_cves
    cve = self.to_cve(id)
  File "D:\workspace\Github\threat-broadcast\src\crawler\cnvd.py", line 73, in to_cve
    self.get_cve_info(cve, cve.url)
  File "D:\workspace\Github\threat-broadcast\src\crawler\cnvd.py", line 101, in get_cve_info
    time.sleep(2)
KeyboardInterrupt
Traceback (most recent call last):
  File "D:\workspace\Github\threat-broadcast\src\crawler\_base_crawler.py", line 62, in cves
    new_cves = self.get_cves()
  File "D:\workspace\Github\threat-broadcast\src\crawler\cnvd.py", line 58, in get_cves
    cve = self.to_cve(id)
  File "D:\workspace\Github\threat-broadcast\src\crawler\cnvd.py", line 73, in to_cve
    self.get_cve_info(cve, cve.url)
  File "D:\workspace\Github\threat-broadcast\src\crawler\cnvd.py", line 101, in get_cve_info
    time.sleep(2)
KeyboardInterrupt
2020-12-02 08:59:19 [ERROR] : [邮件] 推送威胁情报失败
Traceback (most recent call last):
  File "D:\workspace\Github\threat-broadcast\src\notice\mail.py", line 47, in to_mail
    smtpObj.login(sender, password)
  File "S:\04_work\python\python38\lib\smtplib.py", line 734, in login
    raise last_exception
  File "S:\04_work\python\python38\lib\smtplib.py", line 723, in login
    (code, resp) = self.auth(
  File "S:\04_work\python\python38\lib\smtplib.py", line 646, in auth
    raise SMTPAuthenticationError(code, resp)
smtplib.SMTPAuthenticationError: (502, b'Invalid input from 100.107.4.33 to newxmesmtplogicsvrszb5.qq.com')
2020-12-02 08:59:19 [ERROR] : Traceback (most recent call last):
  File "D:\workspace\Github\threat-broadcast\src\notice\mail.py", line 47, in to_mail
    smtpObj.login(sender, password)
  File "S:\04_work\python\python38\lib\smtplib.py", line 734, in login
    raise last_exception
  File "S:\04_work\python\python38\lib\smtplib.py", line 723, in login
    (code, resp) = self.auth(
  File "S:\04_work\python\python38\lib\smtplib.py", line 646, in auth
    raise SMTPAuthenticationError(code, resp)
smtplib.SMTPAuthenticationError: (502, b'Invalid input from 100.107.4.33 to newxmesmtplogicsvrszb5.qq.com')
Traceback (most recent call last):
  File "D:\workspace\Github\threat-broadcast\src\notice\mail.py", line 47, in to_mail
    smtpObj.login(sender, password)
  File "S:\04_work\python\python38\lib\smtplib.py", line 734, in login
    raise last_exception
  File "S:\04_work\python\python38\lib\smtplib.py", line 723, in login
    (code, resp) = self.auth(
  File "S:\04_work\python\python38\lib\smtplib.py", line 646, in auth
    raise SMTPAuthenticationError(code, resp)
smtplib.SMTPAuthenticationError: (502, b'Invalid input from 100.107.4.33 to newxmesmtplogicsvrszb5.qq.com')
